Workbook

Sheet Leyenda
A1: Casos de prueba por HU: proyecto de acompañamiento académico
A3: Composición del Excel
A4: Descripción: En este excel se prueban las Historias de Usuario codificadas por mi autoria es decir Julian Hernández y en algunos casos complementandando historias de usuario de mi compañero Santiago Arteaga, probandose un total de 9 HU, de las 15 HU implementadas hasta la fecha de este segundo semestre.
A5: • Hoja 'Casos de prueba': La hoja de casos de prueba se compone de 8 filas en las cuales se evaluan principalmente, ¿Qué se quiere probar?, Pasos para probar el caso, el resultado que se espera obtener, el resultado que se obtuvo, su estado y en caso de no cumplirse una observación
A6: • Estado tiene una lista desplegable con las condiciones de Pendiente / Pasó / Falló. La hoja 'Resumen' se actualiza sola dependiendo el esatdo de estas y con un porcentaje para saber exactamente que tan completo esta nuestro HU
A7: • Categorías: Ideal (seguir los pasos sin desviarse), Límite (roza los bordes del programa), Peor caso (usuario que prueba de todo).
A8: • Hoja 'Flujos': Esta cuenta con distintas caminos que el usuario podria probar, clasificadas como en tres: camino principal, alternativos (Otras opciones que se despliegan del camino principal) y de error (En el caso de que el usuario pruebe o ingrese datos que el sistema no corresponde) en cada uno de los distintos HU.
A11: Abreviaturas
A12: • " →" El orden de pasos a seguir
A13: • 'Login X / Y' = Menú general → 1 → usuario X → contraseña Y.
A14: • 'Op N' = opción N del menú del rol indicado (administrador, estudiante, monitor o profesor).
A15: • Usuarios base: admin/admin123, estudiante/estu123 (Tatiana, código 1), juan123/carlos123 (Juan Carlos, código 2), monitor/mon123, profesor/prof123.
... A19: • HU-06, 07, 11, 12, 13, 22, 26, 28 y 29: validadas

Sheet Casos de prueba
A1: ID | B1: HU | C1: Categoría | D1: ¿Qué se prueba? | E1: Pasos / entrada | F1: Resultado esperado | G1: Resultado obtenido | H1: Estado | I1: Observaciones
A2: CP-06-01 | B2: HU-06 | C2: Ideal | D2: Ver el historial propio con los datos base | E2: Login estudiante / estu123 → opción 4 | F2: Muestra #1, #2, #3 y #4 en ese orden, cada una con materia, urgencia (Media, Alta, Media, Media), estado (Pendiente, Atendida, Cancelada, Pendiente) y detalle. | G2: El programa muestra correctamente las solicitudes #1 (MAT101, Media, Pendiente), #2 (PROG102, Alta, Atendida), #3 (PROG102, Media, Cancelada) y #4 (FIS105, Media, Pendiente) en orden cronológico con todos sus detalles | H2: Pasó | I2: N/A
A3: CP-06-02 | B3: HU-06 | C3: Ideal | D3: Crear una solicitud, verla en el historial y que persista | E3: Login estudiante → opción 3 → PROG201 → urgencia 2 → 'Ayuda con recursion' → opción 4 → 0 → 0 (guarda) → abrir de nuevo, login y opción 4 | F3: Aparece #5 al final con estado Pendiente y sigue ahí tras reiniciar el programa. | G3: La solicitud #5 se genera correctamente con la materia PROG201, urgencia 2 ycon la descripción de 'Ayuda con recursion'. Al consultar con la opción 4 y tras volver a iniciar sesión, la solicitud #5 se mantiene al final del historial con estado Pendiente | H3: Pasó | I3: N/A
A4: CP-06-03 | B4: HU-06 | C4: Límite | D4: Estudiante sin solicitudes | E4: Login juan123 / carlos123 → opción 4 | F4: Mensaje 'Aun no tienes solicitudes.' y vuelve al menú. | G4: El sistema muestra el mensaje indicando que no hay solicitudes registradas para este usuario y se devuelve al menú principal del estudiante | H4: Pasó | I4: N/A
A5: CP-06-04 | B5: HU-06 | C5: Límite | D5: Aislamiento entre estudiantes | E5: Juan Carlos crea una solicitud (MAT101, urgencia 1, 'Prueba') → opción 4 con Juan → cerrar sesión → login Tatiana → opción 4 | F5: Juan ve solo la suya; Tatiana no ve la de Juan. | G5: Se comprueba el aislamiento de las solicitudes. Juan visualiza únicamente su solicitud recién creada, mientras que al ingresar nuevamente con el usuario Tatiana, el historial de esta estudiante permanece sin alteraciones y sin mostrar la solicitud creada por Juan | H5: Pasó | I5: N/A
A6: CP-06-05 | B6: HU-06 | C6: Límite | D6: Descripción con comas y descripción muy larga | E6: Crear una solicitud con 'Dudas, ayudaaaaaaaaaa, por favor' y otra con 300 caracteres → salir (guarda) → reabrir → opción 4 | F6: Ambas se muestran completas, sin cortarse en la coma. | G6: Ambas solicitudes se despliegan completas en la terminal. Las comas en la descripción 'Dudas, ayudaaaaaaaaaa, por favor' no dividen ni alteran el formato del registro, y la descripción de 300 caracteres se muestra correctamente. | H6: Pasó | I6: N/A
A7: CP-06-06 | B7: HU-06 | C7: Límite | D7: Orden cronológico con el archivo editado a mano | E7: Editar solicitudes.txt dejando los ids en orden 3, 1, 4, 2 → iniciar → login Tatiana → opción 4 | F7: Se muestran en el orden del archivo (3, 1, 4, 2), no ordenadas por id. | G7: Al modificar manualmente el orden de las líneas en el archivo "solicitues.txt" a '3, 1, 4, 2', el sistema despliega el historial del estudiante siguiendo exactamente dicho orden secuencial, sin alterar un orden por ID | H7: Pasó | I7: 'Cronológico' depende del orden en que se guardó; el programa no reordena por id.
A8: CP-06-07 | B8: HU-06 | C8: Límite | D8: Revertir una asignación no altera el historial | E8: Admin op 6 (monitor, MAT101) → op 9 (monitor, 1) → op 7 → login Tatiana → opción 4 | F8: #1 vuelve a Pendiente; las 4 solicitudes siguen en el mismo orden y no se borra ninguna. | G8: Al asignar la solicitud #1 al monitor 'monitor' en MAT101 y posteriormente revertir la asignación desde el rol Administrador, la solicitud #1 regresa correctamente al estado 'Pendiente'. Al consultar el historial del estudiante (opción 4), las 4 solicitudes se conservan, en el mismo orden cronológico y sin perder ningún registro. | H8: Pasó | I8: N/A
A9: CP-06-08 | B9: HU-06 | C9: Peor caso | D9: Opciones de menú inválidas | E9: En el menú estudiante escribir, una por una: abc, cuatro, -4, 44, 99 | F9: Cada una muestra 'Opcion invalida.' sin cerrar el programa ni cambiar el historial. | G9: Al ingresar cada una de las opciones no válidas ('abc', 'cuatro', '-4', '44', '99'), el sistema despliega el mensaje 'Opcion invalida.' y vuelve a mostrar el menú de estudiante | H9: Pasó | I9: N/A
A10: CP-06-09 | B10: HU-06 | C10: Peor caso | D10: Decimal en el menú | E10: En el menú estudiante escribir 4.0 | F10: Ejecuta la opción 4; el '.0' queda en el buffer y el siguiente menú muestra 'Opcion invalida.' una sola vez; luego sigue normal. | G10: Al ingresar '4.0', el sistema ejecuta la opción 4 y despliega el historial. El residuo '.0' genera el mensaje 'Opcion invalida.' una sola vez en el menú posterior y el programa retoma el flujo normal inmediatamente | H10: Pasó | I10: Comportamiento de cin >> int: lee el 4 y deja '.0'.
A11: CP-06-10 | B11: HU-06 | C11: Peor caso | D11: Login con mayúsculas minúsculas alternadas y espacios | E11: ESTUDIANTE/estu123 · estudiante/ESTU123 · EsTuDiAnTe/EsTu123 · 'estu diante'/estu123 | F11: Todos muestran 'Usuario o contrasena incorrectos.'. En el último, el sobrante 'estu123' se lee como opción del menú general y da 'Opcion invalida.'. | G11: Al intentar iniciar sesión con credenciales alteradas ('ESTUDIANTE', 'ESTU123', 'EsTuDiaNTe' o con espacios), el sistema rechaza el acceso mostrando el mensaje de error y evitando el ingreso. | H11: Pasó | I11: El login distingue mayúsculas y cin >> corta en el espacio.
A12: CP-06-11 | B12: HU-06 | C12: Peor caso | D12: Datos inválidos al crear la solicitud | E12: Opción 3 → materia 'mat101' (minúscula) · luego con MAT101 probar urgencia 0, 4, 'alta' y solo espacios | F12: La materia no existe.' y no se crea nada, en urgencia muestra 'Entrada invalida. Ingrese un numero entre 1 y 3.' y repite la pregunta. El historial no cambia. | G12: Al ingresar la materia en minúsculas ('mat101'), el sistema despliega 'La materia no existe.' y retorna al menú. Ante valores de urgencia no válidos (0, 4, 'alta', 'hola?'), el programa captura la excepción, muestra 'Entrada invalida. Ingrese un numero entre 1 y 3.' y vuelve a solicitar el dato sin cerrarse ni registrar información errónea. | H12: Pasó | I12: N/A
... A14: CP-07-02 | B14: HU-07 | C14: Ideal | D14: Atender la siguiente solicitud | E14: Monitor → opción 3 → opción 2 | F14: #1 pasa a Atendida y se muestra; la cola queda solo con #4. | G14: Al seleccionar la opción 3 ('Atender siguiente solicitud'), el sistema toma la solicitud de mayor prioridad en la cola (Solicitud #1), actualiza su estado a 'Atendida' y muestra en pantalla los detalles de la solicitud | H14: Pasó | I14: Se verifica la correcta extracción del nodo cabeza de la cola de prioridad y la transición de estado en tiempo de ejecución.
A15: CP-07-03 | B15: HU-07 | C15: Ideal | D15: Cancelar una solicitud la retira de la cola | E15: Tatiana opción 5 → id 1 → luego monitor opción 2 | F15: La cola muestra solo #4. | H15: Pendiente
A16: CP-07-04 | B16: HU-07 | C16: Ideal | D16: La cola se reconstruye al iniciar | E16: Cerrar el programa sin cambios (0, 0) → abrir → monitor opción 2 | F16: Se ven #1 y #4 como al inicio. | H16: Pendiente
A17: CP-07-05 | B17: HU-07 | C17: Límite | D17: Cola vacía | E17: Monitor opción 3 dos veces (atiende #1 y #4) → opción 3 una tercera vez → opción 2 | F17: Tercera vez y opción 2: 'No hay solicitudes pendientes.' sin errores. | G17: Al atender todas las solicitudes y ejecutar nuevamente la opción 3 o consultar la cola con la opción 2, el programa muestra 'No hay solicitudes pendientes.' en ambas opciones, gestionando el estado de cola vacía sin bloquearse ni lanzar excepciones | H17: Pasó | I17: Se valido el manejo seguro de estructuras de datos vacía
A18: CP-07-06 | B18: HU-07 | C18: Límite | D18: Una sola solicitud en la cola | E18: Dejar solo #1 Pendiente en el archivo → monitor opción 2 → opción 3 | F18: Opción 2 muestra una; opción 3 la atiende y la cola queda vacía. | H18: Pendiente
A19: CP-07-07 | B19: HU-07 | C19: Límite | D19: Archivo sin solicitudes pendientes | E19: Dejar todas en Atendida o Cancelada → iniciar → monitor opción 2 | F19: 'No hay solicitudes pendientes.' | H19: Pendiente
A20: CP-07-08 | B20: HU-07 | C20: Límite | D20: Estado escrito distinto en el archivo | E20: Cambiar #4 a 'pendiente' (minúscula) → iniciar → monitor opción 2 | F20: #4 no aparece en la cola. | H20: Pendiente | I20: Solo se reconstruye con el texto exacto 'Pendiente' (sensible a mayúsculas).
A21: CP-07-09 | B21: HU-07 | C21: Límite | D21: Solicitud Asignada al cerrar el programa | E21: Admin asigna #1 (op 6 y op 9) → cerrar sin deshacer → abrir → monitor opción 2 | F21: #1 vuelve a Pendiente y aparece de nuevo en la cola. | G21: Tras forzar el cierre de la terminal con una solicitud asignada, al reabrir el sistema e ingresar como Monitor, la opción 2 confirma que la solicitud retorna automáticamente al estado 'Pendiente' y se repositiona en la cola de atención manteniendo el orden de prioridad. | H21: Pasó | I21: Se verifico la consistencia del estado de las solicitudes y la resiliencia de la cola de prioridad ante cierres abruptos o interrupciones del programa
A22: CP-07-10 | B22: HU-07 | C22: Límite | D22: Urgencia fuera de rango en el archivo | E22: Cambiar la urgencia de #4 a 7 → iniciar → monitor opción 2 | F22: #4 queda primera en la cola y se muestra con urgencia 'Baja'. | H22: Pendiente | I22: .
A23: CP-07-11 | B23: HU-07 | C23: Peor caso | D23: Menú del monitor con entradas inválidas | E23: Escribir 9, -1, dos, op | F23: 'Opcion invalida.' cada vez; la cola no se altera. | G23: Al ingresar números fuera de rango (como opciones negativas o mayores al límite del menú), el sistema responde indicando que la opción es inválida y vuelve a mostrar el menú del monitor. | H23: Pasó | I23: N/A
A24: CP-07-12 | B24: HU-07 | C24: Peor caso | D24: '3abc' en el menú | E24: Menú monitor → escribir 3abc | F24: Ejecuta 'atender siguiente'; 'abc' sobra y el siguiente menú muestra 'Opcion invalida.' una vez. | G24: Al ingresar '3abc', el programa procesa el primer dígito ('3') como la opción del menú, ejecutando la acción correspondiente, y los caracteres sobrantes ('abc') se consumen de manera controlada en el siguiente ciclo arrojando 'Opcion invalida.' sin generar bucles infinitos ni bloqueos en la terminal | H24: Pasó | I24: N/A
A25: CP-07-13 | B25: HU-07 | C25: Peor caso | D25: Atender repetidas veces con espacios | E25: Con 2 pendientes escribir ' 3 ' tres veces seguidas | F25: Atiende #1, luego #4, y la tercera muestra 'No hay solicitudes pendientes.' | H25: Pendiente
A26: CP-07-14 | B26: HU-07 | C26: Peor caso | D26: Login del monitor con mayúsculas | E26: MONITOR/MON123 · Monitor/mon123 · monitor/Mon123 | F26: 'Usuario o contrasena incorrectos.' en los tres. | H26: Pendiente
A27: CP-08-01 | B27: HU-08 | C27: Ideal | D27: Mayor urgencia primero | E27: Tatiana crea solicitud (MAT101, urgencia 3, 'Urgente') → monitor opción 2 | F27: La nueva queda de primera, antes de #1 y #4. | H27: Pendiente | I27: HU parcial: falta conectar la prioridad con grafos.
A28: CP-08-02 | B28: HU-08 | C28: Ideal | D28: Igual urgencia: la más antigua primero | E28: Crear una solicitud con urgencia 2 → monitor opción 2 | F28: Orden #1, #4, #nueva. | H28: Pendiente
A29: CP-08-03 | B29: HU-08 | C29: Límite | D29: Urgencia mínima queda al final | E29: Crear una solicitud con urgencia 1 → opción 2 | F29: Queda en la última posición. | H29: Pendiente
A30: CP-08-04 | B30: HU-08 | C30: Límite | D30: Una solicitud re-encolada recupera su lugar | E30: Admin op 6 (monitor, MAT101) → op 9 (monitor, 1) → op 7 → monitor opción 2 | F30: #1 vuelve antes que #4 (conserva antigüedad), no al final. | H30: Pendiente
A31: CP-08-05 | B31: HU-08 | C31: Límite | D31: Criterios documentados vs implementados | E31: Revisar ColaSolicitudes::encolar y la documentación de criterios | F31: Solo existen urgencia y antigüedad (id); no hay riesgo académico ni criterios por grafo. | H31: Pendiente | I31: Es la razón por la que la HU pasó a parcial.
A32: CP-08-06 | B32: HU-08 | C32: Peor caso | D32: Urgencia inválida al crear | E32: Opción 3 del estudiante con urgencia 0, 4, -2, 'alta' | F32: 'Entrada invalida. Ingrese un numero entre 1 y 3.' y repite; no se crea nada. | H32: Pendiente
A33: CP-08-07 | B33: HU-08 | C33: Peor caso | D33: Urgencia decimal | E33: Urgencia 2.5 → continuar la creación | F33: Toma 2 como urgencia; el '.5' sobrante se lee como descripción de la solicitud. | H33: Pendiente
A34: CP-08-08 | B34: HU-08 | C34: Peor caso | D34: Muchas solicitudes con la misma urgencia | E34: Crear 10 solicitudes urgencia 3 → monitor opción 2 | F34: Quedan en orden de llegada (id ascendente) dentro del nivel 3. | H34: Pendiente
A35: CP-11-01 | B35: HU-11 | C35: Ideal | D35: Ordenar por urgencia con los datos base | E35: Login admin / admin123 → opción 11 → criterio 1 | F35: Orden #2 (Alta), #1, #3, #4 (Media, la más antigua primero) y '(merge sort: 4 comparaciones)'. | G35: Al ejecutar la opción 5 y ordenar por urgencia (opción 1), el sistema muestra las solicitudes en el orden correcto (#2, #1, #3, #4) utilizando Merge Sort e indicando un total de 5 comparaciones. | H35: Pasó | I35: n/a
A36: CP-11-02 | B36: HU-11 | C36: Ideal | D36: El orden original no se altera | E36: Después de lo anterior → opción 5 | F36: Las solicitudes siguen #1, #2, #3, #4 (orden de llegada). | G36: Tras ejecutar la vista ordenada con Merge Sort (opción 5), al consultar nuevamente todas las solicitudes (opción 1), los datos se muestran en su orden de almacenamiento original, confirmando que la estructura base no sufre modificaciones permanentes | H36: Pasó | I36: El caso CP-11-02 necesitaba del anterior, pero como los dos pasaron las pruebas se valida la inmutabilidad de la estructura de datos frente a las vistas de ordenamiento temporales
A37: CP-11-03 | B37: HU-11 | C37: Límite | D37: Sin solicitudes | E37: Dejar solicitudes.txt vacío → admin opción 11 | F37: 'No hay solicitudes registradas.' | G37: Al intentar ordenar solicitudes con la lista completamente vacía (solicitudes.txt limpio), el sistema maneja la condición de borde de manera controlada mostrando el mensaje 'No hay solicitudes registradas.' sin errores de ejecución. | H37: Pasó | I37: Se valida el algoritmo merge sort frente a conjuntos de datos vacíos.
A38: CP-11-04 | B38: HU-11 | C38: Límite | D38: Una sola solicitud | E38: Dejar solo #1 en el archivo → opción 11 → criterio 1 | F38: Muestra #1 y '0 comparaciones'. | H38: Pendiente
A39: CP-11-05 | B39: HU-11 | C39: Límite | D39: Dos solicitudes | E39: Dejar #1 y #2 → opción 11 → criterio 1 | F39: Orden #2, #1 y '1 comparaciones'. | H39: Pendiente
A40: CP-11-06 | B40: HU-11 | C40: Límite | D40: Todas con la misma urgencia | E40: Poner urgencia 2 en las cuatro → opción 11 → criterio 1 | F40: Quedan por id: #1, #2, #3, #4. | G40: Al ordenar un conjunto de solicitudes que comparten exactamente la misma urgencia, el Merge Sort mantiene la estabilidad de la estructura mostrando las solicitudes en su orden original por ID (#1, #2, #3, #4) y reporta 4 comparaciones | H40: Pasó | I40: Se verifico algoritmo merge sort ante claves de ordenamiento idénticas
A41: CP-11-07 | B41: HU-11 | C41: Límite | D41: Urgencia fuera de rango en el archivo | E41: Urgencia 7 en #4 → opción 11 → criterio 1 | F41: #4 va primero y se muestra como 'Baja'. | H41: Pendiente | I41: Falta validar la urgencia al cargar.
...

Sheet Resumen
A1: HU | B1: Estado de la HU | C1: Total de casos | D1: Pasó | E1: Falló | F1: Pendiente | G1: % que pasó
A2: HU-06 | B2: Validada | C2: =COUNTIF('Casos de prueba'!$B$2:$B$233,A2) -> 11 | D2: =COUNTIFS('Casos de prueba'!$B$2:$B$233,A2,'Casos de prueba'!$H$2:$H$233,"Pasó") -> 11 | E2: =COUNTIFS('Casos de prueba'!$B$2:$B$233,A2,'Casos de prueba'!$H$2:$H$233,"Falló") -> 0 | F2: =COUNTIFS('Casos de prueba'!$B$2:$B$233,A2,'Casos de prueba'!$H$2:$H$233,"Pendiente") -> 0 | G2: =IF(C2=0,0,D2/C2) -> 1
A3: HU-07 | B3: Validada | C3: =COUNTIF('Casos de prueba'!$B$2:$B$233,A3) -> 14 | D3: =COUNTIFS('Casos de prueba'!$B$2:$B$233,A3,'Casos de prueba'!$H$2:$H$233,"Pasó") -> 6 | E3: =COUNTIFS('Casos de prueba'!$B$2:$B$233,A3,'Casos de prueba'!$H$2:$H$233,"Falló") -> 0 | F3: =COUNTIFS('Casos de prueba'!$B$2:$B$233,A3,'Casos de prueba'!$H$2:$H$233,"Pendiente") -> 8 | G3: =IF(C3=0,0,D3/C3) -> 0.42857143
A4: HU-08 | B4: Parcial | C4: =COUNTIF('Casos de prueba'!$B$2:$B$233,A4) -> 8 | D4: =COUNTIFS('Casos de prueba'!$B$2:$B$233,A4,'Casos de prueba'!$H$2:$H$233,"Pasó") -> 0 | E4: =COUNTIFS('Casos de prueba'!$B$2:$B$233,A4,'Casos de prueba'!$H$2:$H$233,"Falló") -> 0 | F4: =COUNTIFS('Casos de prueba'!$B$2:$B$233,A4,'Casos de prueba'!$H$2:$H$233,"Pendiente") -> 8 | G4: =IF(C4=0,0,D4/C4) -> 0
A5: HU-11 | B5: Validada | C5: =COUNTIF('Casos de prueba'!$B$2:$B$233,A5) -> 11 | D5: =COUNTIFS('Casos de prueba'!$B$2:$B$233,A5,'Casos de prueba'!$H$2:$H$233,"Pasó") -> 4 | E5: =COUNTIFS('Casos de prueba'!$B$2:$B$233,A5,'Casos de prueba'!$H$2:$H$233,"Falló") -> 0 | F5: =COUNTIFS('Casos de prueba'!$B$2:$B$233,A5,'Casos de prueba'!$H$2:$H$233,"Pendiente") -> 7 | G5: =IF(C5=0,0,D5/C5) -> 0.36363636
A6: HU-12 | B6: Validada | C6: =COUNTIF('Casos de prueba'!$B$2:$B$233,A6) -> 11 | D6: =COUNTIFS('Casos de prueba'!$B$2:$B$233,A6,'Casos de prueba'!$H$2:$H$233,"Pasó") -> 0 | E6: =COUNTIFS('Casos de prueba'!$B$2:$B$233,A6,'Casos de prueba'!$H$2:$H$233,"Falló") -> 0 | F6: =COUNTIFS('Casos de prueba'!$B$2:$B$233,A6,'Casos de prueba'!$H$2:$H$233,"Pendiente") -> 11 | G6: =IF(C6=0,0,D6/C6) -> 0
A7: HU-13 | B7: Validada | C7: =COUNTIF('Casos de prueba'!$B$2:$B$233,A7) -> 11 | D7: =COUNTIFS('Casos de prueba'!$B$2:$B$233,A7,'Casos de prueba'!$H$2:$H$233,"Pasó") -> 0 | E7: =COUNTIFS('Casos de prueba'!$B$2:$B$233,A7,'Casos de prueba'!$H$2:$H$233,"Falló") -> 0 | F7: =COUNTIFS('Casos de prueba'!$B$2:$B$233,A7,'Casos de prueba'!$H$2:$H$233,"Pendiente") -> 11 | G7: =IF(C7=0,0,D7/C7) -> 0
A8: HU-22 | B8: Validada | C8: =COUNTIF('Casos de prueba'!$B$2:$B$233,A8) -> 14 | D8: =COUNTIFS('Casos de prueba'!$B$2:$B$233,A8,'Casos de prueba'!$H$2:$H$233,"Pasó") -> 0 | E8: =COUNTIFS('Casos de prueba'!$B$2:$B$233,A8,'Casos de prueba'!$H$2:$H$233,"Falló") -> 0 | F8: =COUNTIFS('Casos de prueba'!$B$2:$B$233,A8,'Casos de prueba'!$H$2:$H$233,"Pendiente") -> 14 | G8: =IF(C8=0,0,D8/C8) -> 0
A9: HU-26 | B9: Validada | C9: =COUNTIF('Casos de prueba'!$B$2:$B$233,A9) -> 14 | D9: =COUNTIFS('Casos de prueba'!$B$2:$B$233,A9,'Casos de prueba'!$H$2:$H$233,"Pasó") -> 0 | E9: =COUNTIFS('Casos de prueba'!$B$2:$B$233,A9,'Casos de prueba'!$H$2:$H$233,"Falló") -> 0 | F9: =COUNTIFS('Casos de prueba'!$B$2:$B$233,A9,'Casos de prueba'!$H$2:$H$233,"Pendiente") -> 14 | G9: =IF(C9=0,0,D9/C9) -> 0
A10: HU-28 | B10: Validada | C10: =COUNTIF('Casos de prueba'!$B$2:$B$233,A10) -> 20 | D10: =COUNTIFS('Casos de prueba'!$B$2:$B$233,A10,'Casos de prueba'!$H$2:$H$233,"Pasó") -> 0 | E10: =COUNTIFS('Casos de prueba'!$B$2:$B$233,A10,'Casos de prueba'!$H$2:$H$233,"Falló") -> 0 | F10: =COUNTIFS('Casos de prueba'!$B$2:$B$233,A10,'Casos de prueba'!$H$2:$H$233,"Pendiente") -> 20 | G10: =IF(C10=0,0,D10/C10) -> 0
A11: HU-29 | B11: Validada | C11: =COUNTIF('Casos de prueba'!$B$2:$B$233,A11) -> 18 | D11: =COUNTIFS('Casos de prueba'!$B$2:$B$233,A11,'Casos de prueba'!$H$2:$H$233,"Pasó") -> 0 | E11: =COUNTIFS('Casos de prueba'!$B$2:$B$233,A11,'Casos de prueba'!$H$2:$H$233,"Falló") -> 0 | F11: =COUNTIFS('Casos de prueba'!$B$2:$B$233,A11,'Casos de prueba'!$H$2:$H$233,"Pendiente") -> 18 | G11: =IF(C11=0,0,D11/C11) -> 0
A12: Total | C12: =SUM(C2:C11) -> 132 | D12: =SUM(D2:D11) -> 21 | E12: =SUM(E2:E11) -> 0 | F12: =SUM(F2:F11) -> 111 | G12: =IF(C12=0,0,D12/C12) -> 0.15909091
A14: Los conteos se calculan solos a partir de la columna Estado de la hoja 'Casos de prueba'.

Sheet Flujos
A1: HU | B1: Camino | C1: Tipo | D1: Flujo (paso a paso) | E1: Resultado
A2: HU-06 | B2: A. Ver historial | C2: Principal | D2: Menú general → 1 Iniciar sesión → usuario y clave (Estudiante) → Menú estudiante → 4 → se filtran las solicitudes por código de estudiante → se muestran en orden de llegada → vuelve al menú | E2: Lista con materia, urgencia, estado y detalle
A3: HU-06 | B3: B. Sin solicitudes | C3: Alternativo | D3: Menú estudiante → 4 → no hay coincidencias → mensaje | E3: 'Aun no tienes solicitudes.'
A4: HU-06 | B4: C. Crear y ver | C4: Alternativo | D4: Menú estudiante → 3 → materia válida → urgencia 1-3 → descripción → solicitud creada → 4 | E4: La nueva aparece al final
A5: HU-06 | B5: D. Persistencia | C5: Alternativo | D5: Opción 0 (cerrar sesión) → 0 (salir) → se guarda solicitudes.txt → iniciar de nuevo → carga → login → 4 | E5: El historial se conserva
A6: HU-06 | B6: E. Login inválido | C6: Error | D6: Menú general → 1 → credenciales incorrectas → mensaje de error → Menú general | E6: Sin acceso
A7: HU-06 | B7: F. Opción inválida | C7: Error | D7: Menú estudiante → número fuera de rango o texto → 'Opcion invalida.' → Menú estudiante | E7: Sin cambios
A8: HU-06 | B8: G. Materia inexistente | C8: Error | D8: Menú estudiante → 3 → código que no existe → 'La materia no existe.' → Menú estudiante | E8: No se crea la solicitud
A9: HU-07 | B9: A. Ver cola | C9: Principal | D9: Menú general → 1 Iniciar sesión → usuario y clave (Monitor) → Menú monitor → 2 → recorre la cola → muestra cada solicitud en orden de atención | E9: Cola ordenada
A10: HU-07 | B10: B. Atender siguiente | C10: Alternativo | D10: Menú monitor → 3 → hay frente → se desencola → estado Atendida → se muestra | E10: Solicitud atendida
A11: HU-07 | B11: C. Cola vacía | C11: Alternativo | D11: Menú monitor → 2 o 3 → cola vacía → mensaje | E11: 'No hay solicitudes pendientes.'
A12: HU-07 | B12: D. Cancelación | C12: Alternativo | D12: Estudiante → 5 → id propio pendiente → estado Cancelada → se elimina de la cola | E12: La cola ya no la incluye
... A54: HU-29 | B54: F. Cierre con asignación | C54: Alternativo | D54: Salir sin terminar → se guarda 'Asignada' → al abrir pasa a Pendiente y vuelve a la cola | E54: No se pierde la solicitud
